<?xml version="1.0" ?>
<!-- =================================================================================== -->
<!-- |    This document was autogenerated by xacro from /home/stefano/ros_ws/src/locosim/robot_descriptions/myrobot_description/robots/myrobot.urdf.xacro | -->
<!-- |    EDITING THIS FILE BY HAND IS NOT RECOMMENDED                                 | -->
<!-- =================================================================================== -->
<robot name="myrobot">
  <gazebo>
    <plugin filename="libgazebo_ros_control.so" name="gazebo_ros_controller_manager">
      <robotNamespace>/myrobot</robotNamespace>
      <robotSimType>gazebo_ros_control/DefaultRobotHWSim</robotSimType>
      <legacyModeNS>true</legacyModeNS>
      <controlPeriod>0.004</controlPeriod>
    </plugin>
    <plugin filename="libgazebo_ros_p3d.so" name="gazebo_ros_p3d">
      <robotNamespace>/myrobot</robotNamespace>
      <bodyName>base_link</bodyName>
      <topicName>ground_truth</topicName>
      <frameName>world</frameName>
      <xyzOffsets>0 0 0</xyzOffsets>
      <rpyOffsets>0 0 0</rpyOffsets>
      <gaussianNoise>0</gaussianNoise>
      <alwaysOn>true</alwaysOn>
      <updateRate>250.0</updateRate>
    </plugin>
  </gazebo>
  <link name="base_link">
    <inertial>
      <origin xyz="0.0 0.0 0.0"/>
      <mass value="15"/>
      <inertia ixx="0.001" ixy="0.0" ixz="0.0" iyy="0.001" iyz="0.0" izz="0.001"/>
    </inertial>
    <visual>
      <origin rpy="0 0 0" xyz="0 0.0 0.0"/>
      <geometry>
        <box size="0.1 0.1 0.1"/>
      </geometry>
    </visual>
    <collision>
      <origin rpy="0 0 0" xyz="0 0.0 0.0 "/>
      <geometry>
        <box size="0.1 0.1 0.1"/>
      </geometry>
    </collision>
  </link>
  <joint name="lf_shoulder_pan_joint" type="revolute">
    <parent link="base_link"/>
    <child link="lf_shoulder_link"/>
    <axis xyz="0 0 1"/>
    <origin rpy="0 0 0" xyz="0.1 0.1 0.0"/>
    <limit effort="50" lower="-3.14" upper="3.14" velocity="10.0"/>
  </joint>
  <link name="lf_shoulder_link">
    <inertial>
      <origin xyz="0.0 0.0 0.0"/>
      <mass value="2"/>
      <inertia ixx="0.001" ixy="0.0" ixz="0.0" iyy="0.001" iyz="0.0" izz="0.001"/>
    </inertial>
    <visual>
      <origin rpy="0 0 0" xyz="0 0.0 0.0"/>
      <geometry>
        <box size="0.1 0.1 0.2"/>
      </geometry>
    </visual>
    <collision>
      <origin rpy="0 0 0" xyz="0 0.0 0.0 "/>
      <geometry>
        <box size="0.1 0.1 0.2"/>
      </geometry>
    </collision>
  </link>
  <joint name="lf_foot_fixed" type="fixed">
    <origin rpy="0 0 0" xyz="0 0 -0.1"/>
    <parent link="lf_shoulder_link"/>
    <child link="lf_foot"/>
  </joint>
  <link name="lf_foot">
    <visual>
      <origin rpy="0 0 0" xyz="0 0 0"/>
      <geometry>
        <sphere radius="0.05"/>
      </geometry>
    </visual>
    <collision>
      <origin rpy="0 0 0" xyz="0 0 0"/>
      <geometry>
        <sphere radius="0.05"/>
      </geometry>
    </collision>
  </link>
  <!-- 1st link -->
  <transmission name="lf_shoulder_pan_trans">
    <type>transmission_interface/SimpleTransmission</type>
    <joint name="lf_shoulder_pan_joint">
      <hardwareInterface>hardware_interface/EffortJointInterface</hardwareInterface>
    </joint>
    <actuator name="lf_shoulder_pan_motor">
      <hardwareInterface>hardware_interface/EffortJointInterface</hardwareInterface>
      <mechanicalReduction>1</mechanicalReduction>
    </actuator>
  </transmission>
  <!-- HERE WE HAVE FOOT SENSOR AND FRICTION PROPERTIES -->
  <gazebo reference="lf_foot">
    <kp>1000000.0</kp>
    <kd>100.0</kd>
    <mu1>0.8</mu1>
    <mu2>0.8</mu2>
    <maxVel>1.0</maxVel>
    <maxContacts>1</maxContacts>
    <sensor name="lf_foot_contact_sensor" type="contact">
      <always_on>true</always_on>
      <update_rate>1000.0</update_rate>
      <contact>
        <collision>lf_shoulder_link_collision</collision>
      </contact>
      <plugin filename="libgazebo_ros_bumper.so" name="lf_foot_bumper">
        <bumperTopicName>/myrobot/lf_foot_bumper</bumperTopicName>
        <frameName>lf_foot</frameName>
      </plugin>
    </sensor>
    <material>Gazebo/Black</material>
  </gazebo>
  <joint name="rf_shoulder_pan_joint" type="revolute">
    <parent link="base_link"/>
    <child link="rf_shoulder_link"/>
    <axis xyz="0 0 1"/>
    <origin rpy="0 0 0" xyz="0.1 -0.1 0.0"/>
    <limit effort="50" lower="-3.14" upper="3.14" velocity="10.0"/>
  </joint>
  <link name="rf_shoulder_link">
    <inertial>
      <origin xyz="0.0 0.0 0.0"/>
      <mass value="2"/>
      <inertia ixx="0.001" ixy="0.0" ixz="0.0" iyy="0.001" iyz="0.0" izz="0.001"/>
    </inertial>
    <visual>
      <origin rpy="0 0 0" xyz="0 0.0 0.0"/>
      <geometry>
        <box size="0.1 0.1 0.2"/>
      </geometry>
    </visual>
    <collision>
      <origin rpy="0 0 0" xyz="0 0.0 0.0 "/>
      <geometry>
        <box size="0.1 0.1 0.2"/>
      </geometry>
    </collision>
  </link>
  <joint name="rf_foot_fixed" type="fixed">
    <origin rpy="0 0 0" xyz="0 0 -0.1"/>
    <parent link="rf_shoulder_link"/>
    <child link="rf_foot"/>
  </joint>
  <link name="rf_foot">
    <visual>
      <origin rpy="0 0 0" xyz="0 0 0"/>
      <geometry>
        <sphere radius="0.05"/>
      </geometry>
    </visual>
    <collision>
      <origin rpy="0 0 0" xyz="0 0 0"/>
      <geometry>
        <sphere radius="0.05"/>
      </geometry>
    </collision>
  </link>
  <!-- 1st link -->
  <transmission name="rf_shoulder_pan_trans">
    <type>transmission_interface/SimpleTransmission</type>
    <joint name="rf_shoulder_pan_joint">
      <hardwareInterface>hardware_interface/EffortJointInterface</hardwareInterface>
    </joint>
    <actuator name="rf_shoulder_pan_motor">
      <hardwareInterface>hardware_interface/EffortJointInterface</hardwareInterface>
      <mechanicalReduction>1</mechanicalReduction>
    </actuator>
  </transmission>
  <!-- HERE WE HAVE FOOT SENSOR AND FRICTION PROPERTIES -->
  <gazebo reference="rf_foot">
    <kp>1000000.0</kp>
    <kd>100.0</kd>
    <mu1>0.8</mu1>
    <mu2>0.8</mu2>
    <maxVel>1.0</maxVel>
    <maxContacts>1</maxContacts>
    <sensor name="rf_foot_contact_sensor" type="contact">
      <always_on>true</always_on>
      <update_rate>1000.0</update_rate>
      <contact>
        <collision>rf_shoulder_link_collision</collision>
      </contact>
      <plugin filename="libgazebo_ros_bumper.so" name="rf_foot_bumper">
        <bumperTopicName>/myrobot/rf_foot_bumper</bumperTopicName>
        <frameName>rf_foot</frameName>
      </plugin>
    </sensor>
    <material>Gazebo/Black</material>
  </gazebo>
  <joint name="lh_shoulder_pan_joint" type="revolute">
    <parent link="base_link"/>
    <child link="lh_shoulder_link"/>
    <axis xyz="0 0 1"/>
    <origin rpy="0 0 0" xyz="-0.1 0.1 0.0"/>
    <limit effort="50" lower="-3.14" upper="3.14" velocity="10.0"/>
  </joint>
  <link name="lh_shoulder_link">
    <inertial>
      <origin xyz="0.0 0.0 0.0"/>
      <mass value="2"/>
      <inertia ixx="0.001" ixy="0.0" ixz="0.0" iyy="0.001" iyz="0.0" izz="0.001"/>
    </inertial>
    <visual>
      <origin rpy="0 0 0" xyz="0 0.0 0.0"/>
      <geometry>
        <box size="0.1 0.1 0.2"/>
      </geometry>
    </visual>
    <collision>
      <origin rpy="0 0 0" xyz="0 0.0 0.0 "/>
      <geometry>
        <box size="0.1 0.1 0.2"/>
      </geometry>
    </collision>
  </link>
  <joint name="lh_foot_fixed" type="fixed">
    <origin rpy="0 0 0" xyz="0 0 -0.1"/>
    <parent link="lh_shoulder_link"/>
    <child link="lh_foot"/>
  </joint>
  <link name="lh_foot">
    <visual>
      <origin rpy="0 0 0" xyz="0 0 0"/>
      <geometry>
        <sphere radius="0.05"/>
      </geometry>
    </visual>
    <collision>
      <origin rpy="0 0 0" xyz="0 0 0"/>
      <geometry>
        <sphere radius="0.05"/>
      </geometry>
    </collision>
  </link>
  <!-- 1st link -->
  <transmission name="lh_shoulder_pan_trans">
    <type>transmission_interface/SimpleTransmission</type>
    <joint name="lh_shoulder_pan_joint">
      <hardwareInterface>hardware_interface/EffortJointInterface</hardwareInterface>
    </joint>
    <actuator name="lh_shoulder_pan_motor">
      <hardwareInterface>hardware_interface/EffortJointInterface</hardwareInterface>
      <mechanicalReduction>1</mechanicalReduction>
    </actuator>
  </transmission>
  <!-- HERE WE HAVE FOOT SENSOR AND FRICTION PROPERTIES -->
  <gazebo reference="lh_foot">
    <kp>1000000.0</kp>
    <kd>100.0</kd>
    <mu1>0.8</mu1>
    <mu2>0.8</mu2>
    <maxVel>1.0</maxVel>
    <maxContacts>1</maxContacts>
    <sensor name="lh_foot_contact_sensor" type="contact">
      <always_on>true</always_on>
      <update_rate>1000.0</update_rate>
      <contact>
        <collision>lh_shoulder_link_collision</collision>
      </contact>
      <plugin filename="libgazebo_ros_bumper.so" name="lh_foot_bumper">
        <bumperTopicName>/myrobot/lh_foot_bumper</bumperTopicName>
        <frameName>lh_foot</frameName>
      </plugin>
    </sensor>
    <material>Gazebo/Black</material>
  </gazebo>
  <joint name="rh_shoulder_pan_joint" type="revolute">
    <parent link="base_link"/>
    <child link="rh_shoulder_link"/>
    <axis xyz="0 0 1"/>
    <origin rpy="0 0 0" xyz="-0.1 -0.1 0.0"/>
    <limit effort="50" lower="-3.14" upper="3.14" velocity="10.0"/>
  </joint>
  <link name="rh_shoulder_link">
    <inertial>
      <origin xyz="0.0 0.0 0.0"/>
      <mass value="2"/>
      <inertia ixx="0.001" ixy="0.0" ixz="0.0" iyy="0.001" iyz="0.0" izz="0.001"/>
    </inertial>
    <visual>
      <origin rpy="0 0 0" xyz="0 0.0 0.0"/>
      <geometry>
        <box size="0.1 0.1 0.2"/>
      </geometry>
    </visual>
    <collision>
      <origin rpy="0 0 0" xyz="0 0.0 0.0 "/>
      <geometry>
        <box size="0.1 0.1 0.2"/>
      </geometry>
    </collision>
  </link>
  <joint name="rh_foot_fixed" type="fixed">
    <origin rpy="0 0 0" xyz="0 0 -0.1"/>
    <parent link="rh_shoulder_link"/>
    <child link="rh_foot"/>
  </joint>
  <link name="rh_foot">
    <visual>
      <origin rpy="0 0 0" xyz="0 0 0"/>
      <geometry>
        <sphere radius="0.05"/>
      </geometry>
    </visual>
    <collision>
      <origin rpy="0 0 0" xyz="0 0 0"/>
      <geometry>
        <sphere radius="0.05"/>
      </geometry>
    </collision>
  </link>
  <!-- 1st link -->
  <transmission name="rh_shoulder_pan_trans">
    <type>transmission_interface/SimpleTransmission</type>
    <joint name="rh_shoulder_pan_joint">
      <hardwareInterface>hardware_interface/EffortJointInterface</hardwareInterface>
    </joint>
    <actuator name="rh_shoulder_pan_motor">
      <hardwareInterface>hardware_interface/EffortJointInterface</hardwareInterface>
      <mechanicalReduction>1</mechanicalReduction>
    </actuator>
  </transmission>
  <!-- HERE WE HAVE FOOT SENSOR AND FRICTION PROPERTIES -->
  <gazebo reference="rh_foot">
    <kp>1000000.0</kp>
    <kd>100.0</kd>
    <mu1>0.8</mu1>
    <mu2>0.8</mu2>
    <maxVel>1.0</maxVel>
    <maxContacts>1</maxContacts>
    <sensor name="rh_foot_contact_sensor" type="contact">
      <always_on>true</always_on>
      <update_rate>1000.0</update_rate>
      <contact>
        <collision>rh_shoulder_link_collision</collision>
      </contact>
      <plugin filename="libgazebo_ros_bumper.so" name="rh_foot_bumper">
        <bumperTopicName>/myrobot/rh_foot_bumper</bumperTopicName>
        <frameName>rh_foot</frameName>
      </plugin>
    </sensor>
    <material>Gazebo/Black</material>
  </gazebo>
</robot>
