<?xml version="1.0" ?>
<robot name="starbot" xmlns:xacro="http://ros.org/wiki/xacro">
    
    <!--- new_gazebo_version should be false by default because pinocchio needs it!-->
    <xacro:arg name="robot_name" default="starbot"/> 
    <xacro:arg name="new_gazebo_version" default="false"/>	


    <xacro:include filename="$(find starbot_description)/gazebo/gazebo.urdf.xacro">
        <xacro:arg name="task_period" value="$(arg task_period)"/>
	<xacro:arg name="robot_name" value="$(arg robot_name)"/>
    </xacro:include>

    <xacro:include filename="$(find starbot_description)/urdfs/leg.xacro"/>

    <!-- BASE LINK -->
    <!-- floating type is supported in older versions of Gazebo. In new Gazebo if a link has no parent, it is supposed to be attached to a floating joint -->

    <xacro:unless value="$(arg new_gazebo_version)">  
        <!-- Floating-base Joint -->
        <link name="world"/>
        <joint name="floating_base_joint" type="floating" >
            <origin rpy="0 0 0" xyz="0 0 0"/>
            <parent link="world"/>
            <child link="base_link"/>
        </joint>
    </xacro:unless>

    <link name="base_link" />    
    <joint name="floating_base" type="fixed">
        <origin rpy="0 0 0" xyz="0 0 0"/>
        <parent link="base_link"/>
        <child link="trunk"/>
    </joint>



    
    <link name="trunk">
        <!-- TODO the trunk (it will be fixed to base link but it has inertia) -->
		<inertial>
		  <origin xyz="0.0 0.0 0.0"/>
		  <mass value="15" />
		  <inertia  ixx="0.001" ixy="0.0"  ixz="0.0"  iyy="0.001"  iyz="0.0"  izz="0.001" />
	       </inertial>
	      <visual>
		<origin xyz="0 0.0 0.0" rpy="0 0 0"/>
		<geometry>
		    <box size="0.1 0.1 0.1"/>
		</geometry>
	      </visual>
	     <collision>
		<origin  xyz="0 0.0 0.0 " rpy="0 0 0"/>
		<geometry>
		    <box size="0.1 0.1 0.1"/>
		</geometry>
	     </collision>

    </link>


    <!-- TODO Include the legs (add parameters if necessary)-->
    
    <!-- LEFT FRONT LEG -->
     <xacro:leg
    	name="lf"
    	parent="base_link"
    	robot_name="$(arg robot_name)">
    	<origin xyz="0.1 0.1 0.0" rpy="0 0 0"/>
    </xacro:leg>

    <!-- RIGHT FRONT LEG -->
    <xacro:leg
    	name="rf"
    	parent="base_link"
    	robot_name="$(arg robot_name)">
    	<origin xyz="0.1 -0.1 0.0" rpy="0 0 0"/>
    </xacro:leg>

    <!-- LEFT HIND LEG -->
     <xacro:leg
    	name="lh"
    	parent="base_link"
    	robot_name="$(arg robot_name)">
    	<origin xyz="-0.1 0.1 0.0" rpy="0 0 0"/>
    </xacro:leg>

    <!-- RIGHT HIND LEG -->
    <xacro:leg
    	name="rh"
    	parent="base_link"
    	robot_name="$(arg robot_name)">
    	<origin xyz="-0.1 -0.1 0.0" rpy="0 0 0"/>
    </xacro:leg>


    
</robot>
